Workbook

Sheet Form responses 1
A1: Timestamp | B1: How would you describe your current level in data science: | C1: We are planning to organise a series of talks. Which of the below topics would you be interested in? | D1: Do you know anyone who could give a talk for us related to data science? | E1: Are there any other topics you would like to see talks on? | F1: If we were to organise a course, workshop, or project group, what would you be interested in? | G1: Do you have any other awesome ideas for a workshop or project we can organize? | H1: Are you working at or do you have contacts with a company or organisation which could host one of our meetups? | I1: Name | J1: Email | K1: If you are currently employed, where do you work? (optional) | L1: When would you be available to attend meetups? | M1: Help us organise a talk or course! | N1: If we were to organise a course, workshop, or project group, what would you be interested in?
A2: 42332.828 | B2: I am just getting started | C2: Presenting your data (e.g. Notebook), Programming languages (e.g. R /Python), Scalable analyses (e.g. Spark/Hadoop), Machine learning techniques, Deep learning/neural networks, Data visualisation (e.g. D3.js), Data science and statistics, Data science for marketing, Data science for business analytics, Applications of data science, Text analysis | I2: Anjali | J2: anjalicg2001@gmail | L2: Saturday, Sunday | N2: Learning python, Learning R, Machine learning techniques, Scalable machine learning, Deep learning/Neural networks, Text analysis, Do a project in R/python, Participate in a (beginner or advanced) Kaggle competition, Participate in a hackathon, Go to data science conferences
A3: 42332.834 | B3: I followed a few (online) courses | C3: How to get hired as a data scientist, Scalable analyses (e.g. Spark/Hadoop), Machine learning techniques, Applications of data science, Text analysis | H3: No | I3: Shivva Subramani | J3: itsshivva@gmail.com | K3: Yes | L3: Wednesday evening | N3: Machine learning techniques, Scalable machine learning, Deep learning/Neural networks, Text analysis, Participate in a (beginner or advanced) Kaggle competition, Participate in a hackathon
A4: 42332.847 | B4: I just finished a degree related to datascience | C4: How to get hired as a data scientist, Presenting your data (e.g. Notebook), Programming languages (e.g. R /Python), Scalable analyses (e.g. Spark/Hadoop), Machine learning techniques, Deep learning/neural networks, Data visualisation (e.g. D3.js), Data science and statistics, Data science for marketing, Data science for business analytics, Applications of data science, Text analysis | I4: Poorna Omprakash | J4: poorna.omprakash@gmail.com | K4: Amazon | L4: Friday evening, Saturday, Sunday | M4: Volunteer, study group leader | N4: Learning python, Learning R, Machine learning techniques, Scalable machine learning, Deep learning/Neural networks, Text analysis, Do a project in R/python, Participate in a (beginner or advanced) Kaggle competition, Data scientist interview prep, Participate in a hackathon, Go to data science conferences
A5: 42332.91 | B5: I followed a few (online) courses, I have work experience in a related field but am now transitioning to datascience | C5: How to get hired as a data scientist, Presenting your data (e.g. Notebook), Programming languages (e.g. R /Python), Scalable analyses (e.g. Spark/Hadoop), Machine learning techniques, Deep learning/neural networks, Data visualisation (e.g. D3.js), Data science and statistics, Data science for marketing, Data science for business analytics, Applications of data science, Text analysis | H5: Not now | I5: Emily Wu | J5: emilyxwu@gmail.com | K5: No | L5: Monday evening, Tuesday evening, Wednesday evening, Thursday evening, Friday evening, Saturday, Sunday | M5: I can volunteer 10 hr per month. Happy to help out wherever help is needed. | N5: Learning python, Learning R, Machine learning techniques, Scalable machine learning, Deep learning/Neural networks, Text analysis, Do a project in R/python, Participate in a (beginner or advanced) Kaggle competition, Data scientist interview prep, Participate in a hackathon, Go to data science conferences
A6: 42333.308 | B6: I'm in my first year in a job titled 'software engineer, data science' after many years working as a scientist | C6: Scalable analyses (e.g. Spark/Hadoop), Machine learning techniques, Data visualisation (e.g. D3.js) | D6: I could. I gave a talk for the Women in Business Analytics group on an example of a data story - everything from the data pipeline through analysis and visualization. So far I'm mostly doing data pipelines at my current job, so I could talk more about that, or a talk could be a good excuse to do a personal project with more analysis and visualization. | E6: other languages and tools I've heard about but haven't had time to investigate much: scala, clojure, scalding, elixir always happy to do more D3 since I haven't had much time to play with it on my own, and related tools would love to see a talk about all the new things in the latest matplotlib update wes mckinney gave a great talk on Ibis for a data engineering meetup, it would be great if we could get him or someone to talk about those sorts of tools | G6: Not really, but the last D3 meetup I attended was really good. maybe we could do something with them - I really enjoyed pairing with a designer who knew more javascript but less about data (I know more data and less javascript). | H6: We don't have space right now, but we are moving to a larger office in the near future, at which point it might be doable. | I6: Samantha Zeitlin | J6: samanthazeitlin@gmail.com | K6: Sighten | L6: Monday evening, Tuesday evening, Thursday evening | M6: Can maybe be a speaker or help teach a workshop at some point, but work is pretty busy for me so I'm reluctant to make any promises until I have a better idea how much time I can really spare. | N6: Machine learning techniques, Scalable machine learning
A7: 42336.391 | B7: I am just getting started | C7: Programming languages (e.g. R /Python), Data visualisation (e.g. D3.js), Applications of data science, Text analysis | I7: Jessica Parsons | J7: Verythorough@gmail.com | K7: Freelance part-time | L7: Monday evening, Wednesday evening, Thursday evening, Friday evening, Saturday, Sunday | N7: Learning python, Text analysis, Do a project in R/python, Participate in a (beginner or advanced) Kaggle competition, Participate in a hackathon
A8: 42336.448 | B8: I followed a few (online) courses | C8: How to get hired as a data scientist, Programming languages (e.g. R /Python), Machine learning techniques, Data science for business analytics, Applications of data science | I8: Yong Liu | J8: yliu.bayarea@gmail.com | L8: Wednesday evening, Thursday evening | N8: Do a project in R/python, Participate in a (beginner or advanced) Kaggle competition, Participate in a hackathon, Go to data science conferences
A9: 42336.477 | B9: I am just getting started, I followed a few (online) courses | C9: How to get hired as a data scientist, Presenting your data (e.g. Notebook), Programming languages (e.g. R /Python), Machine learning techniques, Deep learning/neural networks, Data science and statistics, Data science for business analytics, Applications of data science, Text analysis | I9: Raj Sivakumar | J9: raj.a.siva@gmail.com | K9: Start-Up - Thync | L9: Monday evening, Tuesday evening, Wednesday evening, Thursday evening, Friday evening, Saturday, Sunday | M9: I would be interested in co-hosting a Python or R study group that focuses on machine learning techniques. | N9: Learning python, Learning R, Machine learning techniques, Deep learning/Neural networks, Do a project in R/python, Participate in a (beginner or advanced) Kaggle competition, Data scientist interview prep, Participate in a hackathon, Go to data science conferences
A10: 42338.325 | B10: I followed a few (online) courses | C10: How to get hired as a data scientist, Presenting your data (e.g. Notebook), Programming languages (e.g. R /Python), Scalable analyses (e.g. Spark/Hadoop), Machine learning techniques, Data visualisation (e.g. D3.js), Data science and statistics, Applications of data science, Text analysis | G10: A group project in Python where we contribute with GitHub to have as portafolio. | I10: Adriana Rivera | J10: letsgotravel007-meetup@yahoo.com | L10: Tuesday evening, Wednesday evening, Thursday evening | M10: Not sure yet, but I think I could help on some. Still thinking about it. | N10: Learning python, Machine learning techniques, Scalable machine learning, Do a project in R/python, Participate in a (beginner or advanced) Kaggle competition, Data scientist interview prep, Participate in a hackathon, Go to data science conferences
A11: 42338.394 | B11: I manage a data science department | C11: Presenting your data (e.g. Notebook), Machine learning techniques, Deep learning/neural networks, Data visualisation (e.g. D3.js), Text analysis | D11: I can discuss hiring - I'm hiring right now, and I don't know if my hiring process is typical, but I can share what I do. | G11: I would be more interested in high level overviews of these topics rather than deep dive projects. A talk on how a certain technique was applied to a real project would be interesting. | H11: Probably - we're moving into a new space in Santa Clara this month, and we should have room for smaller groups. | I11: Karin Golde | J11: goldehere@gmail.com | K11: NetBase Solutions | L11: Friday evening, Saturday, Sunday | M11: I could add to maybe one talk every one or two months, as a contributor rather than an organizer. | N11: Machine learning techniques, Deep learning/Neural networks
A12: 42338.399 | B12: I am just getting started | C12: Presenting your data (e.g. Notebook), Programming languages (e.g. R /Python), Scalable analyses (e.g. Spark/Hadoop), Machine learning techniques, Data science and statistics, Data science for marketing, Data science for business analytics | I12: Irina | J12: irinacoder1bc@gmail.com | L12: Monday evening, Tuesday evening, Wednesday evening, Thursday evening, Friday evening, Saturday, Sunday | N12: Learning python, Learning R
A13: 42340.194 | B13: I followed a few (online) courses | C13: How to get hired as a data scientist, Presenting your data (e.g. Notebook), Scalable analyses (e.g. Spark/Hadoop), Machine learning techniques, Data visualisation (e.g. D3.js), Data science and statistics, Data science for marketing, Data science for business analytics, Applications of data science, Text analysis | I13: Yumi | J13: Yumi.h.yang@gmail.com | L13: Monday evening, Tuesday evening, Wednesday evening, Thursday evening | N13: Machine learning techniques, Text analysis, Do a project in R/python, Participate in a (beginner or advanced) Kaggle competition, Data scientist interview prep, Participate in a hackathon
A14: 42342.502 | B14: I just finished a degree related to datascience, I have work experience in a related field but am now transitioning to datascience | C14: How to get hired as a data scientist, Presenting your data (e.g. Notebook), Programming languages (e.g. R /Python), Scalable analyses (e.g. Spark/Hadoop), Machine learning techniques, Deep learning/neural networks, Data visualisation (e.g. D3.js), Data science and statistics, Data science for marketing, Data science for business analytics, Applications of data science, Text analysis | I14: luba | J14: lubagloukhova@gmail.com | L14: Tuesday evening, Wednesday evening, Thursday evening, Saturday, Sunday | M14: I would be interested in helping out for ~4h per month. | N14: Do a project in R/python, Participate in a (beginner or advanced) Kaggle competition, Data scientist interview prep, Participate in a hackathon, Go to data science conferences
A15: 42342.585 | B15: I am just getting started | C15: How to get hired as a data scientist, Presenting your data (e.g. Notebook), Programming languages (e.g. R /Python), Scalable analyses (e.g. Spark/Hadoop), Machine learning techniques, Deep learning/neural networks, Data visualisation (e.g. D3.js), Data science and statistics, Data science for marketing, Data science for business analytics, Applications of data science | G15: Intermediate Python, or Python for DS | I15: Dung("yoong") Nguy | J15: yoomzoom@gmail.com | L15: Friday evening, Saturday, Sunday | M15: I would be interest in co-coordinating, helping on any of the topics. ~5-8 hrs per month. | N15: Learning python, Learning R, Machine learning techniques, Scalable machine learning, Deep learning/Neural networks, Do a project in R/python, Participate in a (beginner or advanced) Kaggle competition, Data scientist interview prep, Participate in a hackathon, Go to data science conferences
A16: 42342.601 | B16: I just finished a degree related to datascience, couple internships | C16: Scalable analyses (e.g. Spark/Hadoop), Machine learning techniques, Deep learning/neural networks, Text analysis | E16: I'm interested in topic-specific talks such as image recognition, speech recognition, robotics, autonomous driving. | I16: marjorie | J16: 3marjorie14@gmail.com | L16: Monday evening, Friday evening, Sunday | M16: I'd be interested in being a study group leader or volunteer. I can possibly speak about machine learning techniques (I've taught community college so am a decent speaker). | N16: Deep learning/Neural networks, Participate in a (beginner or advanced) Kaggle competition
A17: 42343.564 | B17: I am just getting started, I followed a few (online) courses, I have work experience in a related field but am now transitioning to datascience | C17: How to get hired as a data scientist, Presenting your data (e.g. Notebook), Programming languages (e.g. R /Python), Machine learning techniques, Data science and statistics, Data science for marketing, Data science for business analytics, Applications of data science | D17: I have a friend who is a data scientist at Google. He is a great teacher and presenter. But he is starting part time PhD program in January, so he doesn't want to commit until he can judge his new load. | G17: How to organize Python development environment on one machine. For example: when you are are working on multiple projects that require different versions of Python or packages. Or if you are working with particular distribution for one project and something different for another one. | I17: Anna Shapiro-Mackler | J17: anna.shapiro@gmail.com | K17: n/a | L17: Monday evening, Tuesday evening, Wednesday evening, Thursday evening, Friday evening, Saturday, Sunday | M17: I am dealing with some health issues for the next at least 3 months. I cannot commit for something regular or being a group leader. I will be happy to help as a volunteer for a particular event if I am available. | N17: Machine learning techniques, Do a project in R/python, Participate in a (beginner or advanced) Kaggle competition, Data scientist interview prep, Participate in a hackathon, Go to data science conferences
A18: 42360.368 | B18: I just finished a degree related to datascience, I have worked a few years as a data scientist | C18: How to get hired as a data scientist, Programming languages (e.g. R /Python), Machine learning techniques, Deep learning/neural networks, Data science and statistics, Data science for marketing, Data science for business analytics, Applications of data science, Text analysis | E18: I think i can help with topics text analysis and ML, NLP | G18: Just crazy ideas: Making some kind of competitions of ML before meet up and discuss at meet up after ( like workshop at conferences) Choose the top articles in confs and ask people to read it at home and prepare short presentation about it. Idea - share new big ideas | I18: Marina Panina | J18: mfpanina@gmail.com | L18: Monday evening, Wednesday evening, Thursday evening | M18: I want to try to be volunteer and help to prepare topics and material on ML, SC, NLP topics. I can spend about average 5hrs/months | N18: Learning R, Text analysis, Data scientist interview prep, Go to data science conferences
A19: 42394.64 | B19: I followed a few (online) courses | C19: How to get hired as a data scientist, Programming languages (e.g. R /Python), Scalable analyses (e.g. Spark/Hadoop), Machine learning techniques, Deep learning/neural networks, Data visualisation (e.g. D3.js), Data science and statistics, Data science for business analytics, Applications of data science, Text analysis | D19: No | E19: No | H19: No | I19: Dhara Mehta | J19: dhara.m44@gmail.com | K19: Nokia | L19: Monday evening, Tuesday evening, Wednesday evening, Thursday evening, Friday evening, Saturday, Sunday | N19: Machine learning techniques, Scalable machine learning, Data scientist interview prep, Participate in a hackathon, Go to data science conferences
A20: 42394.644 | B20: I am just getting started | C20: How to get hired as a data scientist, Machine learning techniques, Data visualisation (e.g. D3.js), Applications of data science | D20: No. | H20: Maybe, I'd have to see who to ask. | L20: Monday evening, Tuesday evening, Wednesday evening, Thursday evening | M20: I can volunteer, but not on weekends.
A21: 42394.652 | B21: I have work experience in a related field but am now transitioning to datascience, Data Engineer supports Data Scientists | C21: Programming languages (e.g. R /Python), Scalable analyses (e.g. Spark/Hadoop), Machine learning techniques, Deep learning/neural networks, Data visualisation (e.g. D3.js), Data science and statistics, Text analysis | E21: Data Engineering - which very close to Data Science. More focus on new technologies and how to integrate them for data science projects. NoSQL databases: Cassandra. | H21: Yes, my company is open to hosting tech talk meetups. | I21: Silvia Oliveros | J21: soliverost@gmail.com | K21: Silicon Valley Data Science | L21: Monday evening, Tuesday evening, Wednesday evening, Thursday evening | M21: I can volunteer in the events, if the events are more technically focused (i.e. Data Engineering) I could help as a group leader. | N21: Machine learning techniques, Scalable machine learning, Deep learning/Neural networks, Participate in a hackathon
A22: 42394.705 | B22: I am just getting started | C22: Presenting your data (e.g. Notebook), Machine learning techniques, Data science and statistics | I22: Bella | J22: amdbpo@gmail.com | K22: Google | L22: Tuesday evening, Wednesday evening, Sunday | N22: Machine learning techniques, Scalable machine learning
A23: 42394.719 | B23: I am just getting started | C23: Presenting your data (e.g. Notebook), Programming languages (e.g. R /Python), Scalable analyses (e.g. Spark/Hadoop), Machine learning techniques, Deep learning/neural networks, Data visualisation (e.g. D3.js), Data science and statistics, Applications of data science, Text analysis | H23: No | I23: Ramya Narayanaswamy | J23: ramya.narayanaswamy@gmail.com | L23: Monday evening, Tuesday evening, Wednesday evening, Thursday evening, Friday evening, Saturday, Sunday | N23: Learning python, Scalable machine learning, Do a project in R/python, Participate in a (beginner or advanced) Kaggle competition, Participate in a hackathon, Go to data science conferences
A24: 42394.743 | B24: I am just getting started | C24: How to get hired as a data scientist, Programming languages (e.g. R /Python), Scalable analyses (e.g. Spark/Hadoop), Machine learning techniques, Deep learning/neural networks | H24: No | I24: Manju | L24: Tuesday evening, Thursday evening | N24: Learning python, Machine learning techniques, Do a project in R/python, Participate in a hackathon, Go to data science conferences
A25: 42394.866 | B25: I have work experience in a related field but am now transitioning to datascience | C25: How to get hired as a data scientist, Programming languages (e.g. R /Python), Scalable analyses (e.g. Spark/Hadoop), Data visualisation (e.g. D3.js), Data science and statistics, Text analysis | H25: n/a | I25: Julia Clavien | J25: julia@juliaclavien.com | K25: n/a | L25: Monday evening, Tuesday evening, Wednesday evening, Thursday evening | M25: I would be interested to do this later in the year | N25: Learning python, Learning R, Machine learning techniques, Text analysis, Do a project in R/python, Participate in a (beginner or advanced) Kaggle competition, Data scientist interview prep
A26: 42394.968 | B26: I am just getting started, I followed a few (online) courses, I have work experience in a related field but am now transitioning to datascience | C26: How to get hired as a data scientist, Presenting your data (e.g. Notebook), Scalable analyses (e.g. Spark/Hadoop), Machine learning techniques, Deep learning/neural networks, Data science and statistics, Text analysis | I26: Antonia Wang | J26: antonia.t.wang@gmail.com | L26: Monday evening, Tuesday evening, Wednesday evening, Thursday evening, Friday evening, Saturday, Sunday | N26: Scalable machine learning, Deep learning/Neural networks, Text analysis, Do a project in R/python, Participate in a (beginner or advanced) Kaggle competition, Data scientist interview prep, Participate in a hackathon
A27: 42395.729 | B27: I am just getting started | C27: Machine learning techniques, Deep learning/neural networks, Data visualisation (e.g. D3.js), Data science and statistics, Applications of data science | I27: Lakshmy Mohanan | J27: lakshmy88@gmail.com | K27: Google | L27: Wednesday evening, Thursday evening, Friday evening | N27: Machine learning techniques, Deep learning/Neural networks, Text analysis, Participate in a (beginner or advanced) Kaggle competition, Participate in a hackathon, Go to data science conferences
A28: 42396.439 | B28: I am just getting started | C28: Scalable analyses (e.g. Spark/Hadoop), Data visualisation (e.g. D3.js), Data science and statistics, Data science for business analytics, Applications of data science | I28: Pushpita Shrestha | J28: ps.puspi@gmail.com | K28: Fujitsu | L28: Saturday, Sunday | N28: Learning R, Participate in a hackathon
A29: 42396.555 | B29: I have work experience in a related field but am now transitioning to datascience | C29: How to get hired as a data scientist, Scalable analyses (e.g. Spark/Hadoop), Deep learning/neural networks, Data visualisation (e.g. D3.js) | I29: Uma | J29: Uma.p.vijh@gmail.com | L29: Wednesday evening, Sunday | N29: Scalable machine learning, Deep learning/Neural networks, Data scientist interview prep, Go to data science conferences
A30: 42396.964 | B30: I followed a few (online) courses | C30: How to get hired as a data scientist, Presenting your data (e.g. Notebook), Programming languages (e.g. R /Python), Scalable analyses (e.g. Spark/Hadoop), Machine learning techniques, Deep learning/neural networks, Data visualisation (e.g. D3.js), Data science and statistics, Data science for marketing, Data science for business analytics, Applications of data science, Text analysis | I30: Yi (Christy) Chou | J30: chrichou33@gmail.com | K30: N/A | L30: Monday evening, Wednesday evening, Saturday | N30: Learning python, Learning R, Machine learning techniques, Do a project in R/python, Participate in a (beginner or advanced) Kaggle competition
A31: 42397.349 | B31: I am just getting started | C31: How to get hired as a data scientist, Presenting your data (e.g. Notebook), Programming languages (e.g. R /Python), Scalable analyses (e.g. Spark/Hadoop), Machine learning techniques, Deep learning/neural networks, Data visualisation (e.g. D3.js), Data science and statistics, Data science for marketing, Data science for business analytics, Applications of data science, Text analysis | H31: Not sure. I will ask. | I31: Masha Rosen | J31: masharosen@yahoo.com | K31: YesVideo Inc | L31: Wednesday evening, Thursday evening | M31: I have experience leading study groups and organizing events, meetups, etc. I can commit to organizing or helping organize study group on Thursday nights. However, I have no experience in Data Science. I have over 20 years experience in software engineering if that helps. | N31: Learning python, Learning R, Machine learning techniques, Scalable machine learning, Deep learning/Neural networks, Text analysis, Do a project in R/python, Go to data science conferences
A32: 42397.381 | B32: I followed a few (online) courses | C32: How to get hired as a data scientist, Presenting your data (e.g. Notebook), Programming languages (e.g. R /Python), Scalable analyses (e.g. Spark/Hadoop), Machine learning techniques, Deep learning/neural networks, Data visualisation (e.g. D3.js), Data science and statistics, Applications of data science | I32: Stephanie Roark | J32: steph.roark@gmail.com | K32: H2O.ai (intern) | L32: Monday evening, Wednesday evening, Thursday evening, Saturday | N32: Learning python, Learning R, Machine learning techniques, Deep learning/Neural networks, Do a project in R/python, Participate in a (beginner or advanced) Kaggle competition, Data scientist interview prep, Participate in a hackathon, Go to data science conferences
A33: 42397.436 | B33: Make some data engineering and analysis but as SWE not as datascience | C33: Scalable analyses (e.g. Spark/Hadoop), Machine learning techniques, Deep learning/neural networks, Data visualisation (e.g. D3.js), Data science and statistics, Data science for marketing, Data science for business analytics, Applications of data science, Text analysis | H33: Not sure, can check | I33: Bella | J33: amdbpo@gmail.com | K33: Google | L33: Tuesday evening, Wednesday evening, Sunday | M33: I have working python experience (currently working in python too) and can help in python course (I am not an official teacher/instructor). | N33: Machine learning techniques, Scalable machine learning, Do a project in R/python, Go to data science conferences
A34: 42397.664 | B34: I am just getting started, I followed a few (online) courses, I just finished a degree related to datascience, I have work experience in a related field but am now transitioning to datascience | C34: How to get hired as a data scientist, Programming languages (e.g. R /Python), Machine learning techniques, Deep learning/neural networks, Data science and statistics, Applications of data science, Text analysis | I34: Fiona Ding | J34: fding253@gmail.com | K34: Santa Clara County | L34: Monday evening, Wednesday evening, Friday evening, Saturday, Sunday | M34: I'd be happy to help out with anything (as long as it doesn't require too much prior expertise...). ~10-15 hr/month. | N34: Learning python, Learning R, Machine learning techniques, Scalable machine learning, Deep learning/Neural networks, Text analysis, Do a project in R/python, Participate in a (beginner or advanced) Kaggle competition, Data scientist interview prep, Participate in a hackathon, Go to data science conferences
A35: 42397.718 | B35: Preparing, my company will need this function in the next year | C35: Presenting your data (e.g. Notebook), Scalable analyses (e.g. Spark/Hadoop), Machine learning techniques, Deep learning/neural networks, Data visualisation (e.g. D3.js), Data science and statistics, Data science for business analytics | I35: Stacie Frederick | J35: stacie@alum.calberkeley.org | L35: Monday evening, Thursday evening | N35: Learning python, Machine learning techniques, Scalable machine learning, Deep learning/Neural networks, Do a project in R/python
A36: 42398.407 | B36: I followed a few (online) courses, I have work experience in a related field but am now transitioning to datascience | C36: How to get hired as a data scientist, Presenting your data (e.g. Notebook), Programming languages (e.g. R /Python), Scalable analyses (e.g. Spark/Hadoop), Machine learning techniques, Deep learning/neural networks, Data visualisation (e.g. D3.js), Data science and statistics, Data science for marketing, Data science for business analytics, Applications of data science, Text analysis | D36: I have a friend who is in industry that can speak about his work but will need to confirm with him first if he can do it. | E36: Support Vector Machines, big data, TensorFlow, appications of data science in medical field | G36: Handling large datasets, SQL workshops | I36: Grace Ma | J36: gma0930@gmail.com | K36: biotech firm | L36: Monday evening, Tuesday evening, Wednesday evening, Friday evening, Saturday, Sunday | M36: I'd like to volunteer as an organizer, 6-8 hrs a month. | N36: Learning python, Machine learning techniques, Scalable machine learning, Deep learning/Neural networks, Do a project in R/python, Go to data science conferences
A37: 42401.953 | B37: I am just getting started, I followed a few (online) courses | C37: How to get hired as a data scientist, Presenting your data (e.g. Notebook), Programming languages (e.g. R /Python), Scalable analyses (e.g. Spark/Hadoop), Machine learning techniques, Deep learning/neural networks, Data visualisation (e.g. D3.js), Data science and statistics, Data science for marketing, Data science for business analytics, Applications of data science, Text analysis | D37: I know a couple of data scientists but not sure if they would like to give a talk. They are all based in San Francisco. | I37: Jaya | J37: jayavijayen@hotmail.com | K37: Job Hunting | L37: Tuesday evening, Thursday evening, Saturday | M37: I'd like to volunteer and help out at data science meetups. | N37: Learning python, Learning R, Machine learning techniques, Scalable machine learning, Deep learning/Neural networks, Text analysis, Do a project in R/python, Participate in a (beginner or advanced) Kaggle competition, Data scientist interview prep, Participate in a hackathon
A38: 42403.901 | B38: I have work experience in a related field but am now transitioning to datascience | C38: How to get hired as a data scientist, Programming languages (e.g. R /Python), Scalable analyses (e.g. Spark/Hadoop), Machine learning techniques, Deep learning/neural networks, Data visualisation (e.g. D3.js), Data science and statistics, Applications of data science, Text analysis | H38: My husband works for Ericsson (the office is in North San Jose). He says that it is quite likely that they can offer room (probably the cafeteria) for talks. I'll need to check this. | I38: Judit Lantos | J38: lantosjudit@gmail.com | K38: Stanford University, Welocalize | L38: Monday evening, Tuesday evening, Wednesday evening, Thursday evening, Friday evening, Saturday, Sunday | M38: I'd be glad to get involved in a study group but I'm not sure if I can offer enough expertise. I'll go to the next hiking meetup and will ask one of you in person. | N38: Learning python, Machine learning techniques, Scalable machine learning, Deep learning/Neural networks, Text analysis, Do a project in R/python, Participate in a (beginner or advanced) Kaggle competition, Data scientist interview prep
A39: 42407.794 | B39: I am just getting started, I followed a few (online) courses, current stats grad student | C39: How to get hired as a data scientist, Presenting your data (e.g. Notebook), Programming languages (e.g. R /Python), Scalable analyses (e.g. Spark/Hadoop), Machine learning techniques, Deep learning/neural networks, Data visualisation (e.g. D3.js), Data science and statistics, Data science for marketing, Data science for business analytics, Applications of data science, Text analysis | I39: Maria nazari | J39: Marianazari510@gmail.com | L39: Saturday, Sunday | N39: Learning python, Learning R, Machine learning techniques, Scalable machine learning, Deep learning/Neural networks, Text analysis, Do a project in R/python, Participate in a (beginner or advanced) Kaggle competition, Data scientist interview prep, Participate in a hackathon, Go to data science conferences
A40: 42409.492 | B40: I am just getting started, I just finished a degree related to datascience | C40: Presenting your data (e.g. Notebook), Programming languages (e.g. R /Python), Scalable analyses (e.g. Spark/Hadoop), Machine learning techniques, Deep learning/neural networks, Data visualisation (e.g. D3.js), Data science and statistics, Applications of data science, Text analysis | I40: Ramya Narayanaswamy | J40: ramya.narayanaswamy@gmail.com | L40: Monday evening, Tuesday evening, Wednesday evening, Thursday evening, Friday evening, Saturday, Sunday | M40: I am interested in volunteering for Data Science meetups. My hours of availability differ from week to week. | N40: Learning python, Learning R, Machine learning techniques, Scalable machine learning, Deep learning/Neural networks, Text analysis, Do a project in R/python, Participate in a (beginner or advanced) Kaggle competition, Participate in a hackathon, Go to data science conferences
...

Sheet Sheet2
B2: ='Form responses 1'!M2 | C2: ='Form responses 1'!J2 -> anjalicg2001@gmail
B3: ='Form responses 1'!M3 | C3: ='Form responses 1'!J3 -> itsshivva@gmail.com
B4: ='Form responses 1'!M4 -> Volunteer, study group leader | C4: ='Form responses 1'!J4 -> poorna.omprakash@gmail.com
B5: ='Form responses 1'!M5 -> I can volunteer 10 hr per month. Happy to help out wherever help is needed. | C5: ='Form responses 1'!J5 -> emilyxwu@gmail.com
B6: ='Form responses 1'!M6 -> Can maybe be a speaker or help teach a workshop at some point, but work is pretty busy for me so I'm reluctant to make any promises until I have a better idea how much time I can really spare. | C6: ='Form responses 1'!J6 -> samanthazeitlin@gmail.com
B7: ='Form responses 1'!M7 | C7: ='Form responses 1'!J7 -> Verythorough@gmail.com
B8: ='Form responses 1'!M8 | C8: ='Form responses 1'!J8 -> yliu.bayarea@gmail.com
B9: ='Form responses 1'!M9 -> I would be interested in co-hosting a Python or R study group that focuses on machine learning techniques. | C9: ='Form responses 1'!J9 -> raj.a.siva@gmail.com
B10: ='Form responses 1'!M10 -> Not sure yet, but I think I could help on some. Still thinking about it. | C10: ='Form responses 1'!J10 -> letsgotravel007-meetup@yahoo.com
B11: ='Form responses 1'!M11 -> I could add to maybe one talk every one or two months, as a contributor rather than an organizer. | C11: ='Form responses 1'!J11 -> goldehere@gmail.com
B12: ='Form responses 1'!M12 | C12: ='Form responses 1'!J12 -> irinacoder1bc@gmail.com
B13: ='Form responses 1'!M13 | C13: ='Form responses 1'!J13 -> Yumi.h.yang@gmail.com
... B43: ='Form responses 1'!M43 -> 7-8 hours a month. I would love to volunteer or be a study group leader. I am not sure if I am a qualified speaker - but if you think I am- I would love to speak | C43: ='Form responses 1'!J43 -> srishti.gupta28@gmail.com
B44: ='Form responses 1'!M45 | C44: ='Form responses 1'!J45
B45: ='Form responses 1'!M46 | C45: ='Form responses 1'!J46
B46: ='Form responses 1'!M47 | C46: ='Form responses 1'!J47
B47: ='Form responses 1'!M48 | C47: ='Form responses 1'!J48
B48: ='Form responses 1'!M49 | C48: ='Form responses 1'!J49
B49: ='Form responses 1'!M50 | C49: ='Form responses 1'!J50
B50: ='Form responses 1'!M51 | C50: ='Form responses 1'!J51
B51: ='Form responses 1'!M52 | C51: ='Form responses 1'!J52
B52: ='Form responses 1'!M53 | C52: ='Form responses 1'!J53
B53: ='Form responses 1'!M54 | C53: ='Form responses 1'!J54
B54: ='Form responses 1'!M55 | C54: ='Form responses 1'!J55
B55: ='Form responses 1'!M56 | C55: ='Form responses 1'!J56
... B63: ='Form responses 1'!M64 | C63: ='Form responses 1'!J64
